Workbook

Sheet Read Me
B6: Wilkins Media - Military On-Base Advertising Rate Card (MASTER)
B7: Generated September 29, 2026 from the standardized rate card (data/rate_card.csv).
B9: What this is | C9: One row per media option on each installation, with the VENDOR (base) cost at 1 / 3 / 6 / 12 months and production. Client prices are formulas driven by the Settings tab, so changing the margin re-prices every line.
B10: Source | C10: Box > Military > Master Grid > "MasterMilitaryOnBaseList 12.2.25 NS.xlsx", cleaned and normalized. Base populations are reference values from "Military - National Digital Inventory Master 6.3.26.xlsx".
B11: How to update a price | C11: Edit the Vendor Cost cells on the Rate Card tab. Put the year of the rate card you used in "Rate Card Year" and today's date in "Last Updated". Do not type into the Client Price columns - they are formulas.
B12: How to add a base or option | C12: Add a row at the bottom of the Rate Card table (the table extends automatically). Fill Base, State, DMA, Branch, Category, Media Type, Size, Description and the vendor costs you know. Leave unknown terms blank.
B13: Pricing conventions | C13: Vendor Cost columns are TOTALS for that term (3 Months = total for a 3-month flight). Where a base only sells a longer term, the 1 Month column is blank and Min Term shows the shortest term sold. Marquees and other per-unit items are priced per unit unless the description says otherwise.
B14: Client price rule | C14: Client Price = Vendor Cost / (1 - margin), rounded to the nearest $25 (Settings tab). Standard military margin is 50% (vendor x 2). Competitive bids may use a lower margin - change it in the proposal builder, not here.
B15: Production | C15: Production is never included in the media price. Standard production (quantity of 1): Poster 22x28 $100, Banner 3x6 $350. Other sizes: inquire. Where a base quoted its own production, it is in the Vendor Production Cost column.
B16: Review Flag | C16: "No price on file" = the base lists the item but we have no cost (inquire). "Rate card older than 2025" = reconfirm with the base before quoting. "Source formula errors" = the old master had #VALUE! in that row; verify against the base rate card in Box > Military > 2 Military Installations.
B17: Box source | C17: Every row carries the Box folder of the installation and the newest rate-card file in it ("Open in Box"). When you take a price from a new file, paste its Box link in the app (Update pricing) or in these columns.
B18: Proposal builder | C18: The web app (military/index.html in the EMC_AI_Tool repo) reads this file: use "Load rate card" in the app to pull in your latest edits, then build the proposal and export the client and internal Excel files.

Sheet Settings
A1: Setting | B1: Value | C1: Notes
A2: Standard margin (share of client price kept by Wilkins) | B2: 0.5 | C2: Client price = Vendor cost / (1 - margin). 50% = vendor x 2, the standard military markup. Competitive bids have used 30%.
A3: Round client prices to nearest | B3: 25 | C3: Matches the rounding used in the prior master list ($25).
A4: Standard production - Poster 22"W x 28"H (client price) | B4: 100 | C4: Per David, Sep 22 2026 (raised because frames must ship separately).
A5: Standard production - Banner 3'H x 6'W (client price) | B5: 350 | C5: Per David, Sep 22 2026.
A6: Est. printer cost - Poster | B6: 50 | C6: Estimate; update from the printer quote.
A7: Est. printer cost - Banner 3x6 | B7: 96 | C7: Printer quote (Cecily): $95.51 with ground shipping.
A8: Default campaign length (months) | B8: 3 | C8: A one-month campaign is not as effective; pricing is quoted on a three-month campaign.
A9: Standard pricing method | B9: Monthly rate x months | C9: House rule: use the 1-month rate x months (not the discounted term price) unless it is a competitive bid.
A10: Rate card year considered current | B10: 2025 | C10: Cards from 2025/2026 are good; older cards should be reconfirmed with the base.

Sheet Rate Card
A1: ID | B1: Base | C1: Also known as | D1: State | E1: DMA / Metro | F1: Zip | G1: Branch | H1: Category | I1: Media Type | J1: Ad Unit Size | K1: Description | L1: Min Term (mo) | M1: Vendor Cost 1 Month | N1: Vendor Cost 3 Months | O1: Vendor Cost 6 Months | P1: Vendor Cost 12 Months | Q1: Vendor Production Cost | R1: Client Price 1 Month | S1: Client Price 3 Months | T1: Client Price 6 Months | U1: Client Price 12 Months | V1: Client Production Price | W1: Active Duty (ref.) | X1: Dependents (ref.) | Y1: Rate Card Year | Z1: Last Updated | AA1: Notes | AB1: Review Flag | AC1: Source | AD1: Rate card file in Box | AE1: Link to rate card file | AF1: Box folder
A2: AK-EIELSONA-001 | B2: Eielson AFB | D2: AK | E2: Fairbanks | F2: 99702 | G2: Air Force | H2: Digital | I2: Digital Monitor Network | J2: 1920pxW x 1080pxH | K2: Your static ad will appear on the indoor digital monitors in on-base facilities. | L2: 1 | M2: 200 | N2: 600 | O2: 1100 | P2: 2100 | Q2: 0 | R2: =IF(ISNUMBER(M2),ROUND(M2/(1-Settings!$B$2)/Settings!$B$3,0)*Settings!$B$3,"") | S2: =IF(ISNUMBER(N2),ROUND(N2/(1-Settings!$B$2)/Settings!$B$3,0)*Settings!$B$3,"") | T2: =IF(ISNUMBER(O2),ROUND(O2/(1-Settings!$B$2)/Settings!$B$3,0)*Settings!$B$3,"") | U2: =IF(ISNUMBER(P2),ROUND(P2/(1-Settings!$B$2)/Settings!$B$3,0)*Settings!$B$3,"") | V2: =IF(ISNUMBER(Q2),ROUND(Q2/(1-Settings!$B$2)/Settings!$B$3,0)*Settings!$B$3,"") | W2: 1958 | X2: 2424 | AA2: Inventory master 6/2026 lists Digital Marquee at $3,000 (1 mo) | AC2: MasterMilitaryOnBaseList 12.2.25 NS.xlsx | AD2: Eielson AFB_Advertising Rates_2026.pptx | AE2: Open in Box | AF2: Open in Box
A3: AK-EIELSONA-002 | B3: Eielson AFB | D3: AK | E3: Fairbanks | F3: 99702 | G3: Air Force | H3: Digital | I3: Outdoor Marquee | J3: TBD | K3: Your ad will appear on one outdoor marquee. | L3: 1 | M3: 1000 | N3: 3000 | O3: 5500 | P3: 10500 | Q3: 0 | R3: =IF(ISNUMBER(M3),ROUND(M3/(1-Settings!$B$2)/Settings!$B$3,0)*Settings!$B$3,"") | S3: =IF(ISNUMBER(N3),ROUND(N3/(1-Settings!$B$2)/Settings!$B$3,0)*Settings!$B$3,"") | T3: =IF(ISNUMBER(O3),ROUND(O3/(1-Settings!$B$2)/Settings!$B$3,0)*Settings!$B$3,"") | U3: =IF(ISNUMBER(P3),ROUND(P3/(1-Settings!$B$2)/Settings!$B$3,0)*Settings!$B$3,"") | V3: =IF(ISNUMBER(Q3),ROUND(Q3/(1-Settings!$B$2)/Settings!$B$3,0)*Settings!$B$3,"") | W3: 1958 | X3: 2424 | AA3: Inventory master 6/2026 lists Digital Marquee at $3,000 (1 mo) | AC3: MasterMilitaryOnBaseList 12.2.25 NS.xlsx | AD3: Eielson AFB_Advertising Rates_2026.pptx | AE3: Open in Box | AF3: Open in Box
A4: AK-EIELSONA-005 | B4: Eielson AFB | D4: AK | E4: Fairbanks | F4: 99702 | G4: Air Force | H4: Print & Publications | I4: Brochure/Flyer Placement | J4: TBD | K4: Your brochure or flyer will be distributed in an approved installation facility. | L4: 1 | M4: 50 | N4: 150 | O4: 275 | P4: 525 | Q4: 0 | R4: =IF(ISNUMBER(M4),ROUND(M4/(1-Settings!$B$2)/Settings!$B$3,0)*Settings!$B$3,"") | S4: =IF(ISNUMBER(N4),ROUND(N4/(1-Settings!$B$2)/Settings!$B$3,0)*Settings!$B$3,"") | T4: =IF(ISNUMBER(O4),ROUND(O4/(1-Settings!$B$2)/Settings!$B$3,0)*Settings!$B$3,"") | U4: =IF(ISNUMBER(P4),ROUND(P4/(1-Settings!$B$2)/Settings!$B$3,0)*Settings!$B$3,"") | V4: =IF(ISNUMBER(Q4),ROUND(Q4/(1-Settings!$B$2)/Settings!$B$3,0)*Settings!$B$3,"") | W4: 1958 | X4: 2424 | AC4: MasterMilitaryOnBaseList 12.2.25 NS.xlsx | AD4: Eielson AFB_Advertising Rates_2026.pptx | AE4: Open in Box | AF4: Open in Box
A5: AK-EIELSONA-006 | B5: Eielson AFB | D5: AK | E5: Fairbanks | F5: 99702 | G5: Air Force | H5: Sponsorship & Other | I5: Newcomers Info Fair | J5: TBD | K5: Newcomers Info Fair is held once a month in the Yukon Ballroom | L5: 1 | M5: 50 | N5: 150 | O5: 300 | P5: 600 | Q5: 0 | R5: =IF(ISNUMBER(M5),ROUND(M5/(1-Settings!$B$2)/Settings!$B$3,0)*Settings!$B$3,"") | S5: =IF(ISNUMBER(N5),ROUND(N5/(1-Settings!$B$2)/Settings!$B$3,0)*Settings!$B$3,"") | T5: =IF(ISNUMBER(O5),ROUND(O5/(1-Settings!$B$2)/Settings!$B$3,0)*Settings!$B$3,"") | U5: =IF(ISNUMBER(P5),ROUND(P5/(1-Settings!$B$2)/Settings!$B$3,0)*Settings!$B$3,"") | V5: =IF(ISNUMBER(Q5),ROUND(Q5/(1-Settings!$B$2)/Settings!$B$3,0)*Settings!$B$3,"") | W5: 1958 | X5: 2424 | AC5: MasterMilitaryOnBaseList 12.2.25 NS.xlsx | AD5: Eielson AFB_Advertising Rates_2026.pptx | AE5: Open in Box | AF5: Open in Box
A6: AK-EIELSONA-003 | B6: Eielson AFB | D6: AK | E6: Fairbanks | F6: 99702 | G6: Air Force | H6: Standard Media | I6: Banners | J6: TBD | K6: Your Banner will be hung in an approved on base facilities | L6: 1 | M6: 1000 | N6: 3000 | O6: 5500 | P6: 10500 | Q6: 200 | R6: =IF(ISNUMBER(M6),ROUND(M6/(1-Settings!$B$2)/Settings!$B$3,0)*Settings!$B$3,"") | S6: =IF(ISNUMBER(N6),ROUND(N6/(1-Settings!$B$2)/Settings!$B$3,0)*Settings!$B$3,"") | T6: =IF(ISNUMBER(O6),ROUND(O6/(1-Settings!$B$2)/Settings!$B$3,0)*Settings!$B$3,"") | U6: =IF(ISNUMBER(P6),ROUND(P6/(1-Settings!$B$2)/Settings!$B$3,0)*Settings!$B$3,"") | V6: =IF(ISNUMBER(Q6),ROUND(Q6/(1-Settings!$B$2)/Settings!$B$3,0)*Settings!$B$3,"") | W6: 1958 | X6: 2424 | AC6: MasterMilitaryOnBaseList 12.2.25 NS.xlsx | AD6: Eielson AFB_Advertising Rates_2026.pptx | AE6: Open in Box | AF6: Open in Box
A7: AK-EIELSONA-004 | B7: Eielson AFB | D7: AK | E7: Fairbanks | F7: 99702 | G7: Air Force | H7: Standard Media | I7: Product Display | K7: Your product will be displayed at an approved installation facility. | L7: 1 | M7: 1000 | N7: 3000 | O7: 5500 | P7: 10500 | Q7: 0 | R7: =IF(ISNUMBER(M7),ROUND(M7/(1-Settings!$B$2)/Settings!$B$3,0)*Settings!$B$3,"") | S7: =IF(ISNUMBER(N7),ROUND(N7/(1-Settings!$B$2)/Settings!$B$3,0)*Settings!$B$3,"") | T7: =IF(ISNUMBER(O7),ROUND(O7/(1-Settings!$B$2)/Settings!$B$3,0)*Settings!$B$3,"") | U7: =IF(ISNUMBER(P7),ROUND(P7/(1-Settings!$B$2)/Settings!$B$3,0)*Settings!$B$3,"") | V7: =IF(ISNUMBER(Q7),ROUND(Q7/(1-Settings!$B$2)/Settings!$B$3,0)*Settings!$B$3,"") | W7: 1958 | X7: 2424 | AC7: MasterMilitaryOnBaseList 12.2.25 NS.xlsx | AD7: Eielson AFB_Advertising Rates_2026.pptx | AE7: Open in Box | AF7: Open in Box
A8: AK-EIELSONA-008 | B8: Eielson AFB | D8: AK | E8: Fairbanks | G8: Air Force | H8: Web & Email | I8: Web Ad | K8: Your ad will appear on the installation MWR / FSS website. | L8: 1 | M8: 1000 | R8: =IF(ISNUMBER(M8),ROUND(M8/(1-Settings!$B$2)/Settings!$B$3,0)*Settings!$B$3,"") | S8: =IF(ISNUMBER(N8),ROUND(N8/(1-Settings!$B$2)/Settings!$B$3,0)*Settings!$B$3,"") | T8: =IF(ISNUMBER(O8),ROUND(O8/(1-Settings!$B$2)/Settings!$B$3,0)*Settings!$B$3,"") | U8: =IF(ISNUMBER(P8),ROUND(P8/(1-Settings!$B$2)/Settings!$B$3,0)*Settings!$B$3,"") | V8: =IF(ISNUMBER(Q8),ROUND(Q8/(1-Settings!$B$2)/Settings!$B$3,0)*Settings!$B$3,"") | W8: 1958 | X8: 2424 | Y8: 2026 | Z8: 2026-06 | AC8: Military - National Publication Inventory Master_June 2026.xlsx | AD8: Eielson AFB_Advertising Rates_2026.pptx | AE8: Open in Box | AF8: Open in Box
A9: AK-EIELSONA-007 | B9: Eielson AFB | D9: AK | E9: Fairbanks | G9: Air Force | H9: Web & Email | I9: Weekly E-Newsletter Ad | K9: Your ad will appear in the weekly e-newsletter emailed to the installation community. | L9: 1 | M9: 50 | R9: =IF(ISNUMBER(M9),ROUND(M9/(1-Settings!$B$2)/Settings!$B$3,0)*Settings!$B$3,"") | S9: =IF(ISNUMBER(N9),ROUND(N9/(1-Settings!$B$2)/Settings!$B$3,0)*Settings!$B$3,"") | T9: =IF(ISNUMBER(O9),ROUND(O9/(1-Settings!$B$2)/Settings!$B$3,0)*Settings!$B$3,"") | U9: =IF(ISNUMBER(P9),ROUND(P9/(1-Settings!$B$2)/Settings!$B$3,0)*Settings!$B$3,"") | V9: =IF(ISNUMBER(Q9),ROUND(Q9/(1-Settings!$B$2)/Settings!$B$3,0)*Settings!$B$3,"") | W9: 1958 | X9: 2424 | Y9: 2026 | Z9: 2026-06 | AC9: Military - National Publication Inventory Master_June 2026.xlsx | AD9: Eielson AFB_Advertising Rates_2026.pptx | AE9: Open in Box | AF9: Open in Box
A10: AK-FORTGREE-001 | B10: Fort Greely | D10: AK | E10: Fairbanks, AK | G10: Army | H10: Digital | I10: Digital Marquee | J10: 3 screens | K10: Your ad will appear on the 3-screen digital marquee(s) on the installation. | L10: 1 | M10: 75 | R10: =IF(ISNUMBER(M10),ROUND(M10/(1-Settings!$B$2)/Settings!$B$3,0)*Settings!$B$3,"") | S10: =IF(ISNUMBER(N10),ROUND(N10/(1-Settings!$B$2)/Settings!$B$3,0)*Settings!$B$3,"") | T10: =IF(ISNUMBER(O10),ROUND(O10/(1-Settings!$B$2)/Settings!$B$3,0)*Settings!$B$3,"") | U10: =IF(ISNUMBER(P10),ROUND(P10/(1-Settings!$B$2)/Settings!$B$3,0)*Settings!$B$3,"") | V10: =IF(ISNUMBER(Q10),ROUND(Q10/(1-Settings!$B$2)/Settings!$B$3,0)*Settings!$B$3,"") | Y10: 2026 | Z10: 2026-06 | AC10: Military - National Digital Inventory Master 6.3.26.xlsx | AD10: USAG Alaska Advertising Flyer_2026.png | AE10: Open in Box | AF10: Open in Box
A11: AK-FORTGREE-002 | B11: Fort Greely | D11: AK | E11: Fairbanks, AK | G11: Army | H11: Web & Email | I11: Web Ad | K11: Your ad will appear on the installation MWR / FSS website. | L11: 3 | N11: 50 | R11: =IF(ISNUMBER(M11),ROUND(M11/(1-Settings!$B$2)/Settings!$B$3,0)*Settings!$B$3,"") | S11: =IF(ISNUMBER(N11),ROUND(N11/(1-Settings!$B$2)/Settings!$B$3,0)*Settings!$B$3,"") | T11: =IF(ISNUMBER(O11),ROUND(O11/(1-Settings!$B$2)/Settings!$B$3,0)*Settings!$B$3,"") | U11: =IF(ISNUMBER(P11),ROUND(P11/(1-Settings!$B$2)/Settings!$B$3,0)*Settings!$B$3,"") | V11: =IF(ISNUMBER(Q11),ROUND(Q11/(1-Settings!$B$2)/Settings!$B$3,0)*Settings!$B$3,"") | W11: 407 | Y11: 2026 | Z11: 2026-06 | AA11: Sold quarterly | AC11: Military - National Publication Inventory Master_June 2026.xlsx | AD11: USAG Alaska Advertising Flyer_2026.png | AE11: Open in Box | AF11: Open in Box
A12: AK-FORTJONA-001 | B12: Fort Jonathan Wainwright | D12: AK | E12: Fairbanks, AK | G12: Army | H12: Digital | I12: Digital Marquee | J12: 7 screens | K12: Your ad will appear on the 7-screen digital marquee(s) on the installation. | L12: 1 | M12: 700 | R12: =IF(ISNUMBER(M12),ROUND(M12/(1-Settings!$B$2)/Settings!$B$3,0)*Settings!$B$3,"") | S12: =IF(ISNUMBER(N12),ROUND(N12/(1-Settings!$B$2)/Settings!$B$3,0)*Settings!$B$3,"") | T12: =IF(ISNUMBER(O12),ROUND(O12/(1-Settings!$B$2)/Settings!$B$3,0)*Settings!$B$3,"") | U12: =IF(ISNUMBER(P12),ROUND(P12/(1-Settings!$B$2)/Settings!$B$3,0)*Settings!$B$3,"") | V12: =IF(ISNUMBER(Q12),ROUND(Q12/(1-Settings!$B$2)/Settings!$B$3,0)*Settings!$B$3,"") | W12: 6117 | X12: 6995 | Y12: 2026 | Z12: 2026-06 | AC12: Military - National Digital Inventory Master 6.3.26.xlsx | AD12: USAG Alaska Advertising Flyer_2026.png | AE12: Open in Box | AF12: Open in Box
A13: AK-FORTJONA-002 | B13: Fort Jonathan Wainwright | D13: AK | E13: Fairbanks, AK | G13: Army | H13: Web & Email | I13: Web Ad | K13: Your ad will appear on the installation MWR / FSS website. | L13: 3 | N13: 300 | R13: =IF(ISNUMBER(M13),ROUND(M13/(1-Settings!$B$2)/Settings!$B$3,0)*Settings!$B$3,"") | S13: =IF(ISNUMBER(N13),ROUND(N13/(1-Settings!$B$2)/Settings!$B$3,0)*Settings!$B$3,"") | T13: =IF(ISNUMBER(O13),ROUND(O13/(1-Settings!$B$2)/Settings!$B$3,0)*Settings!$B$3,"") | U13: =IF(ISNUMBER(P13),ROUND(P13/(1-Settings!$B$2)/Settings!$B$3,0)*Settings!$B$3,"") | V13: =IF(ISNUMBER(Q13),ROUND(Q13/(1-Settings!$B$2)/Settings!$B$3,0)*Settings!$B$3,"") | W13: 6117 | X13: 6995 | Y13: 2026 | Z13: 2026-06 | AA13: Sold quarterly | AC13: Military - National Publication Inventory Master_June 2026.xlsx | AD13: USAG Alaska Advertising Flyer_2026.png | AE13: Open in Box | AF13: Open in Box
A14: AK-JBERELME-001 | B14: JBER - Elmendorf AFB | C14: Joint Base Elmendorf-Richardson | D14: AK | E14: Anchorage | F14: 99506 | G14: Air Force | H14: Digital | I14: Bowling Score Monitors | K14: Your ad will be shown on the monitors in the largest bowling center in the Air Force | L14: 3 | N14: 750 | O14: 1500 | P14: 3000 | Q14: 0 | R14: =IF(ISNUMBER(M14),ROUND(M14/(1-Settings!$B$2)/Settings!$B$3,0)*Settings!$B$3,"") | S14: =IF(ISNUMBER(N14),ROUND(N14/(1-Settings!$B$2)/Settings!$B$3,0)*Settings!$B$3,"") | T14: =IF(ISNUMBER(O14),ROUND(O14/(1-Settings!$B$2)/Settings!$B$3,0)*Settings!$B$3,"") | U14: =IF(ISNUMBER(P14),ROUND(P14/(1-Settings!$B$2)/Settings!$B$3,0)*Settings!$B$3,"") | V14: =IF(ISNUMBER(Q14),ROUND(Q14/(1-Settings!$B$2)/Settings!$B$3,0)*Settings!$B$3,"") | W14: 5504 | X14: 7035 | AA14: Inventory master 6/2026 lists Golf Scorecard Ad at $500 (3 mo) | AC14: MasterMilitaryOnBaseList 12.2.25 NS.xlsx | AD14: Sponsorship & Advertising Rate Sheet_2026.pdf | AE14: Open in Box | AF14: Open in Box
A15: AK-JBERELME-002 | B15: JBER - Elmendorf AFB | C15: Joint Base Elmendorf-Richardson | D15: AK | E15: Anchorage | F15: 99506 | G15: Air Force | H15: Digital | I15: Bowling Table Tents | K15: Your ad will be on table tents placed on the tables in the largest bowling center in the Air Force | L15: 3 | N15: 600 | O15: 1200 | P15: 1000 | Q15: 0 | R15: =IF(ISNUMBER(M15),ROUND(M15/(1-Settings!$B$2)/Settings!$B$3,0)*Settings!$B$3,"") | S15: =IF(ISNUMBER(N15),ROUND(N15/(1-Settings!$B$2)/Settings!$B$3,0)*Settings!$B$3,"") | T15: =IF(ISNUMBER(O15),ROUND(O15/(1-Settings!$B$2)/Settings!$B$3,0)*Settings!$B$3,"") | U15: =IF(ISNUMBER(P15),ROUND(P15/(1-Settings!$B$2)/Settings!$B$3,0)*Settings!$B$3,"") | V15: =IF(ISNUMBER(Q15),ROUND(Q15/(1-Settings!$B$2)/Settings!$B$3,0)*Settings!$B$3,"") | W15: 5504 | X15: 7035 | AC15: MasterMilitaryOnBaseList 12.2.25 NS.xlsx | AD15: Sponsorship & Advertising Rate Sheet_2026.pdf | AE15: Open in Box | AF15: Open in Box
A16: AK-JBERELME-003 | B16: JBER - Elmendorf AFB | C16: Joint Base Elmendorf-Richardson | D16: AK | E16: Anchorage | F16: 99506 | G16: Air Force | H16: Digital | I16: Digital Monitor Network | K16: Your ad will appear on 36 digital monitors. | L16: 3 | N16: 800 | O16: 1600 | P16: 3200 | Q16: 0 | R16: =IF(ISNUMBER(M16),ROUND(M16/(1-Settings!$B$2)/Settings!$B$3,0)*Settings!$B$3,"") | S16: =IF(ISNUMBER(N16),ROUND(N16/(1-Settings!$B$2)/Settings!$B$3,0)*Settings!$B$3,"") | T16: =IF(ISNUMBER(O16),ROUND(O16/(1-Settings!$B$2)/Settings!$B$3,0)*Settings!$B$3,"") | U16: =IF(ISNUMBER(P16),ROUND(P16/(1-Settings!$B$2)/Settings!$B$3,0)*Settings!$B$3,"") | V16: =IF(ISNUMBER(Q16),ROUND(Q16/(1-Settings!$B$2)/Settings!$B$3,0)*Settings!$B$3,"") | W16: 5504 | X16: 7035 | AC16: MasterMilitaryOnBaseList 12.2.25 NS.xlsx | AD16: Sponsorship & Advertising Rate Sheet_2026.pdf | AE16: Open in Box | AF16: Open in Box
A17: AK-JBERELME-004 | B17: JBER - Elmendorf AFB | C17: Joint Base Elmendorf-Richardson | D17: AK | E17: Anchorage | F17: 99506 | G17: Air Force | H17: Digital | I17: Lane Sweepers | K17: Your ad will cover 40 lanes | L17: 12 | P17: 5000 | Q17: 0 | R17: =IF(ISNUMBER(M17),ROUND(M17/(1-Settings!$B$2)/Settings!$B$3,0)*Settings!$B$3,"") | S17: =IF(ISNUMBER(N17),ROUND(N17/(1-Settings!$B$2)/Settings!$B$3,0)*Settings!$B$3,"") | T17: =IF(ISNUMBER(O17),ROUND(O17/(1-Settings!$B$2)/Settings!$B$3,0)*Settings!$B$3,"") | U17: =IF(ISNUMBER(P17),ROUND(P17/(1-Settings!$B$2)/Settings!$B$3,0)*Settings!$B$3,"") | V17: =IF(ISNUMBER(Q17),ROUND(Q17/(1-Settings!$B$2)/Settings!$B$3,0)*Settings!$B$3,"") | W17: 5504 | X17: 7035 | AC17: MasterMilitaryOnBaseList 12.2.25 NS.xlsx | AD17: Sponsorship & Advertising Rate Sheet_2026.pdf | AE17: Open in Box | AF17: Open in Box
A18: AK-JBERELME-009 | B18: JBER - Elmendorf AFB | C18: Joint Base Elmendorf-Richardson | D18: AK | E18: Anchorage | F18: 99506 | G18: Air Force | H18: Large Format | I18: Snow Fencing | K18: Your ad will appear on a snow fence from November - May at Hillberg Ski Area | L18: 12 | P18: 10000 | Q18: 0 | R18: =IF(ISNUMBER(M18),ROUND(M18/(1-Settings!$B$2)/Settings!$B$3,0)*Settings!$B$3,"") | S18: =IF(ISNUMBER(N18),ROUND(N18/(1-Settings!$B$2)/Settings!$B$3,0)*Settings!$B$3,"") | T18: =IF(ISNUMBER(O18),ROUND(O18/(1-Settings!$B$2)/Settings!$B$3,0)*Settings!$B$3,"") | U18: =IF(ISNUMBER(P18),ROUND(P18/(1-Settings!$B$2)/Settings!$B$3,0)*Settings!$B$3,"") | V18: =IF(ISNUMBER(Q18),ROUND(Q18/(1-Settings!$B$2)/Settings!$B$3,0)*Settings!$B$3,"") | W18: 5504 | X18: 7035 | AC18: MasterMilitaryOnBaseList 12.2.25 NS.xlsx | AD18: Sponsorship & Advertising Rate Sheet_2026.pdf | AE18: Open in Box | AF18: Open in Box
A19: AK-JBERELME-010 | B19: JBER - Elmendorf AFB | C19: Joint Base Elmendorf-Richardson | D19: AK | E19: Anchorage | F19: 99506 | G19: Air Force | H19: Print & Publications | I19: Cabin Book Ads | K19: Your ad will appear in the cabin book ads seasonally (May - September) | L19: 3 | N19: 500 | Q19: 0 | R19: =IF(ISNUMBER(M19),ROUND(M19/(1-Settings!$B$2)/Settings!$B$3,0)*Settings!$B$3,"") | S19: =IF(ISNUMBER(N19),ROUND(N19/(1-Settings!$B$2)/Settings!$B$3,0)*Settings!$B$3,"") | T19: =IF(ISNUMBER(O19),ROUND(O19/(1-Settings!$B$2)/Settings!$B$3,0)*Settings!$B$3,"") | U19: =IF(ISNUMBER(P19),ROUND(P19/(1-Settings!$B$2)/Settings!$B$3,0)*Settings!$B$3,"") | V19: =IF(ISNUMBER(Q19),ROUND(Q19/(1-Settings!$B$2)/Settings!$B$3,0)*Settings!$B$3,"") | W19: 5504 | X19: 7035 | AC19: MasterMilitaryOnBaseList 12.2.25 NS.xlsx | AD19: Sponsorship & Advertising Rate Sheet_2026.pdf | AE19: Open in Box | AF19: Open in Box
A20: AK-JBERELME-011 | B20: JBER - Elmendorf AFB | C20: Joint Base Elmendorf-Richardson | D20: AK | E20: Anchorage | F20: 99506 | G20: Air Force | H20: Print & Publications | I20: Golf Score Cards | K20: Your ads will appear on the score cards from May - September at the Moose Run Golf Course | L20: 12 | P20: 500 | Q20: 0 | R20: =IF(ISNUMBER(M20),ROUND(M20/(1-Settings!$B$2)/Settings!$B$3,0)*Settings!$B$3,"") | S20: =IF(ISNUMBER(N20),ROUND(N20/(1-Settings!$B$2)/Settings!$B$3,0)*Settings!$B$3,"") | T20: =IF(ISNUMBER(O20),ROUND(O20/(1-Settings!$B$2)/Settings!$B$3,0)*Settings!$B$3,"") | U20: =IF(ISNUMBER(P20),ROUND(P20/(1-Settings!$B$2)/Settings!$B$3,0)*Settings!$B$3,"") | V20: =IF(ISNUMBER(Q20),ROUND(Q20/(1-Settings!$B$2)/Settings!$B$3,0)*Settings!$B$3,"") | W20: 5504 | X20: 7035 | AA20: Inventory master 6/2026 lists Golf Scorecard Ad at $500 (3 mo) | AC20: MasterMilitaryOnBaseList 12.2.25 NS.xlsx | AD20: Sponsorship & Advertising Rate Sheet_2026.pdf | AE20: Open in Box | AF20: Open in Box
A21: AK-JBERELME-012 | B21: JBER - Elmendorf AFB | C21: Joint Base Elmendorf-Richardson | D21: AK | E21: Anchorage | F21: 99506 | G21: Air Force | H21: Print & Publications | I21: Magazine Ad | J21: Full Page | K21: Your ad will appear in the JBER Life! Magazine (a 40 page magazine with 5,000 copies distributed across the installation and published online) | L21: 1 | M21: 500 | N21: 1500 | O21: 3000 | P21: 6000 | Q21: 0 | R21: =IF(ISNUMBER(M21),ROUND(M21/(1-Settings!$B$2)/Settings!$B$3,0)*Settings!$B$3,"") | S21: =IF(ISNUMBER(N21),ROUND(N21/(1-Settings!$B$2)/Settings!$B$3,0)*Settings!$B$3,"") | T21: =IF(ISNUMBER(O21),ROUND(O21/(1-Settings!$B$2)/Settings!$B$3,0)*Settings!$B$3,"") | U21: =IF(ISNUMBER(P21),ROUND(P21/(1-Settings!$B$2)/Settings!$B$3,0)*Settings!$B$3,"") | V21: =IF(ISNUMBER(Q21),ROUND(Q21/(1-Settings!$B$2)/Settings!$B$3,0)*Settings!$B$3,"") | W21: 5504 | X21: 7035 | AA21: Inventory master 6/2026 lists Magazine Ad at $800 (3 mo) | AC21: MasterMilitaryOnBaseList 12.2.25 NS.xlsx | AD21: Sponsorship & Advertising Rate Sheet_2026.pdf | AE21: Open in Box | AF21: Open in Box
A22: AK-JBERELME-013 | B22: JBER - Elmendorf AFB | C22: Joint Base Elmendorf-Richardson | D22: AK | E22: Anchorage | F22: 99506 | G22: Air Force | H22: Print & Publications | I22: Summer Outdoor Adventure Guide | K22: 10,000 copies combined circulated installation wide and published online. Produced once for summer and once for winter. | L22: 12 | P22: 900 | Q22: 0 | R22: =IF(ISNUMBER(M22),ROUND(M22/(1-Settings!$B$2)/Settings!$B$3,0)*Settings!$B$3,"") | S22: =IF(ISNUMBER(N22),ROUND(N22/(1-Settings!$B$2)/Settings!$B$3,0)*Settings!$B$3,"") | T22: =IF(ISNUMBER(O22),ROUND(O22/(1-Settings!$B$2)/Settings!$B$3,0)*Settings!$B$3,"") | U22: =IF(ISNUMBER(P22),ROUND(P22/(1-Settings!$B$2)/Settings!$B$3,0)*Settings!$B$3,"") | V22: =IF(ISNUMBER(Q22),ROUND(Q22/(1-Settings!$B$2)/Settings!$B$3,0)*Settings!$B$3,"") | W22: 5504 | X22: 7035 | AA22: Inventory master 6/2026 lists Guide / Map Ad at $900 (3 mo) | AC22: MasterMilitaryOnBaseList 12.2.25 NS.xlsx | AD22: Sponsorship & Advertising Rate Sheet_2026.pdf | AE22: Open in Box | AF22: Open in Box
A23: AK-JBERELME-014 | B23: JBER - Elmendorf AFB | C23: Joint Base Elmendorf-Richardson | D23: AK | E23: Anchorage | F23: 99506 | G23: Air Force | H23: Print & Publications | I23: Winter Outdoor Adventure Guide | K23: 10,000 copies combined circulated installation wide and published online. $100 discount when you advertise in both books. Deadline: September 15 | L23: 12 | P23: 700 | Q23: 0 | R23: =IF(ISNUMBER(M23),ROUND(M23/(1-Settings!$B$2)/Settings!$B$3,0)*Settings!$B$3,"") | S23: =IF(ISNUMBER(N23),ROUND(N23/(1-Settings!$B$2)/Settings!$B$3,0)*Settings!$B$3,"") | T23: =IF(ISNUMBER(O23),ROUND(O23/(1-Settings!$B$2)/Settings!$B$3,0)*Settings!$B$3,"") | U23: =IF(ISNUMBER(P23),ROUND(P23/(1-Settings!$B$2)/Settings!$B$3,0)*Settings!$B$3,"") | V23: =IF(ISNUMBER(Q23),ROUND(Q23/(1-Settings!$B$2)/Settings!$B$3,0)*Settings!$B$3,"") | W23: 5504 | X23: 7035 | AA23: Inventory master 6/2026 lists Guide / Map Ad at $900 (3 mo) | AC23: MasterMilitaryOnBaseList 12.2.25 NS.xlsx | AD23: Sponsorship & Advertising Rate Sheet_2026.pdf | AE23: Open in Box | AF23: Open in Box
A24: AK-JBERELME-015 | B24: JBER - Elmendorf AFB | C24: Joint Base Elmendorf-Richardson | D24: AK | E24: Anchorage | F24: 99506 | G24: Air Force | H24: Sponsorship & Other | I24: Canopy - Golf Course | K24: Your ads will appear on a canopy from May - September at the Moose Run Golf Course | L24: 12 | P24: 1000 | Q24: 0 | R24: =IF(ISNUMBER(M24),ROUND(M24/(1-Settings!$B$2)/Settings!$B$3,0)*Settings!$B$3,"") | S24: =IF(ISNUMBER(N24),ROUND(N24/(1-Settings!$B$2)/Settings!$B$3,0)*Settings!$B$3,"") | T24: =IF(ISNUMBER(O24),ROUND(O24/(1-Settings!$B$2)/Settings!$B$3,0)*Settings!$B$3,"") | U24: =IF(ISNUMBER(P24),ROUND(P24/(1-Settings!$B$2)/Settings!$B$3,0)*Settings!$B$3,"") | V24: =IF(ISNUMBER(Q24),ROUND(Q24/(1-Settings!$B$2)/Settings!$B$3,0)*Settings!$B$3,"") | W24: 5504 | X24: 7035 | AC24: MasterMilitaryOnBaseList 12.2.25 NS.xlsx | AD24: Sponsorship & Advertising Rate Sheet_2026.pdf | AE24: Open in Box | AF24: Open in Box
A25: AK-JBERELME-016 | B25: JBER - Elmendorf AFB | C25: Joint Base Elmendorf-Richardson | D25: AK | E25: Anchorage | F25: 99506 | G25: Air Force | H25: Sponsorship & Other | I25: Chairlift - Ski Area | K25: Your ad will appear on a chairlift from November - March at the Hillberg Ski Area | L25: 12 | P25: 500 | Q25: 0 | R25: =IF(ISNUMBER(M25),ROUND(M25/(1-Settings!$B$2)/Settings!$B$3,0)*Settings!$B$3,"") | S25: =IF(ISNUMBER(N25),ROUND(N25/(1-Settings!$B$2)/Settings!$B$3,0)*Settings!$B$3,"") | T25: =IF(ISNUMBER(O25),ROUND(O25/(1-Settings!$B$2)/Settings!$B$3,0)*Settings!$B$3,"") | U25: =IF(ISNUMBER(P25),ROUND(P25/(1-Settings!$B$2)/Settings!$B$3,0)*Settings!$B$3,"") | V25: =IF(ISNUMBER(Q25),ROUND(Q25/(1-Settings!$B$2)/Settings!$B$3,0)*Settings!$B$3,"") | W25: 5504 | X25: 7035 | AC25: MasterMilitaryOnBaseList 12.2.25 NS.xlsx | AD25: Sponsorship & Advertising Rate Sheet_2026.pdf | AE25: Open in Box | AF25: Open in Box
A26: AK-JBERELME-017 | B26: JBER - Elmendorf AFB | C26: Joint Base Elmendorf-Richardson | D26: AK | E26: Anchorage | F26: 99506 | G26: Air Force | H26: Sponsorship & Other | I26: Driving Range Dividers | K26: Your ad will appear on a single the driving range dividers at the Moose Run Golf Course from May - September. | L26: 12 | P26: 350 | Q26: 0 | R26: =IF(ISNUMBER(M26),ROUND(M26/(1-Settings!$B$2)/Settings!$B$3,0)*Settings!$B$3,"") | S26: =IF(ISNUMBER(N26),ROUND(N26/(1-Settings!$B$2)/Settings!$B$3,0)*Settings!$B$3,"") | T26: =IF(ISNUMBER(O26),ROUND(O26/(1-Settings!$B$2)/Settings!$B$3,0)*Settings!$B$3,"") | U26: =IF(ISNUMBER(P26),ROUND(P26/(1-Settings!$B$2)/Settings!$B$3,0)*Settings!$B$3,"") | V26: =IF(ISNUMBER(Q26),ROUND(Q26/(1-Settings!$B$2)/Settings!$B$3,0)*Settings!$B$3,"") | W26: 5504 | X26: 7035 | AC26: MasterMilitaryOnBaseList 12.2.25 NS.xlsx | AD26: Sponsorship & Advertising Rate Sheet_2026.pdf | AE26: Open in Box | AF26: Open in Box
A27: AK-JBERELME-018 | B27: JBER - Elmendorf AFB | C27: Joint Base Elmendorf-Richardson | D27: AK | E27: Anchorage | F27: 99506 | G27: Air Force | H27: Sponsorship & Other | I27: Newcomers Info Bag | K27: Your ad will appear in the installation newcomers info bags. | L27: 3 | N27: 525 | O27: 1000 | P27: 2000 | Q27: 0 | R27: =IF(ISNUMBER(M27),ROUND(M27/(1-Settings!$B$2)/Settings!$B$3,0)*Settings!$B$3,"") | S27: =IF(ISNUMBER(N27),ROUND(N27/(1-Settings!$B$2)/Settings!$B$3,0)*Settings!$B$3,"") | T27: =IF(ISNUMBER(O27),ROUND(O27/(1-Settings!$B$2)/Settings!$B$3,0)*Settings!$B$3,"") | U27: =IF(ISNUMBER(P27),ROUND(P27/(1-Settings!$B$2)/Settings!$B$3,0)*Settings!$B$3,"") | V27: =IF(ISNUMBER(Q27),ROUND(Q27/(1-Settings!$B$2)/Settings!$B$3,0)*Settings!$B$3,"") | W27: 5504 | X27: 7035 | AC27: MasterMilitaryOnBaseList 12.2.25 NS.xlsx | AD27: Sponsorship & Advertising Rate Sheet_2026.pdf | AE27: Open in Box | AF27: Open in Box
A28: AK-JBERELME-005 | B28: JBER - Elmendorf AFB | C28: Joint Base Elmendorf-Richardson | D28: AK | E28: Anchorage | F28: 99506 | G28: Air Force | H28: Standard Media | I28: Banners | K28: Your ad will apper in an approved installation facility. | L28: 6 | O28: 1000 | P28: 2000 | Q28: 200 | R28: =IF(ISNUMBER(M28),ROUND(M28/(1-Settings!$B$2)/Settings!$B$3,0)*Settings!$B$3,"") | S28: =IF(ISNUMBER(N28),ROUND(N28/(1-Settings!$B$2)/Settings!$B$3,0)*Settings!$B$3,"") | T28: =IF(ISNUMBER(O28),ROUND(O28/(1-Settings!$B$2)/Settings!$B$3,0)*Settings!$B$3,"") | U28: =IF(ISNUMBER(P28),ROUND(P28/(1-Settings!$B$2)/Settings!$B$3,0)*Settings!$B$3,"") | V28: =IF(ISNUMBER(Q28),ROUND(Q28/(1-Settings!$B$2)/Settings!$B$3,0)*Settings!$B$3,"") | W28: 5504 | X28: 7035 | AC28: MasterMilitaryOnBaseList 12.2.25 NS.xlsx | AD28: Sponsorship & Advertising Rate Sheet_2026.pdf | AE28: Open in Box | AF28: Open in Box
A29: AK-JBERELME-006 | B29: JBER - Elmendorf AFB | C29: Joint Base Elmendorf-Richardson | D29: AK | E29: Anchorage | F29: 99506 | G29: Air Force | H29: Standard Media | I29: Golf Tee Signs | K29: Your ads will appear at one hole during golf season from May - September at the Moose Run Golf Course | L29: 12 | P29: 700 | Q29: 0 | R29: =IF(ISNUMBER(M29),ROUND(M29/(1-Settings!$B$2)/Settings!$B$3,0)*Settings!$B$3,"") | S29: =IF(ISNUMBER(N29),ROUND(N29/(1-Settings!$B$2)/Settings!$B$3,0)*Settings!$B$3,"") | T29: =IF(ISNUMBER(O29),ROUND(O29/(1-Settings!$B$2)/Settings!$B$3,0)*Settings!$B$3,"") | U29: =IF(ISNUMBER(P29),ROUND(P29/(1-Settings!$B$2)/Settings!$B$3,0)*Settings!$B$3,"") | V29: =IF(ISNUMBER(Q29),ROUND(Q29/(1-Settings!$B$2)/Settings!$B$3,0)*Settings!$B$3,"") | W29: 5504 | X29: 7035 | AC29: MasterMilitaryOnBaseList 12.2.25 NS.xlsx | AD29: Sponsorship & Advertising Rate Sheet_2026.pdf | AE29: Open in Box | AF29: Open in Box
A30: AK-JBERELME-007 | B30: JBER - Elmendorf AFB | C30: Joint Base Elmendorf-Richardson | D30: AK | E30: Anchorage | F30: 99506 | G30: Air Force | H30: Standard Media | I30: Posters | J30: 22"W x 28"H | K30: Your ad will appear at an approved installation facility. | L30: 3 | N30: 300 | O30: 600 | P30: 1200 | Q30: 100 | R30: =IF(ISNUMBER(M30),ROUND(M30/(1-Settings!$B$2)/Settings!$B$3,0)*Settings!$B$3,"") | S30: =IF(ISNUMBER(N30),ROUND(N30/(1-Settings!$B$2)/Settings!$B$3,0)*Settings!$B$3,"") | T30: =IF(ISNUMBER(O30),ROUND(O30/(1-Settings!$B$2)/Settings!$B$3,0)*Settings!$B$3,"") | U30: =IF(ISNUMBER(P30),ROUND(P30/(1-Settings!$B$2)/Settings!$B$3,0)*Settings!$B$3,"") | V30: =IF(ISNUMBER(Q30),ROUND(Q30/(1-Settings!$B$2)/Settings!$B$3,0)*Settings!$B$3,"") | W30: 5504 | X30: 7035 | AC30: MasterMilitaryOnBaseList 12.2.25 NS.xlsx | AD30: Sponsorship & Advertising Rate Sheet_2026.pdf | AE30: Open in Box | AF30: Open in Box
A31: AK-JBERELME-008 | B31: JBER - Elmendorf AFB | C31: Joint Base Elmendorf-Richardson | D31: AK | E31: Anchorage | F31: 99507 | G31: Air Force | H31: Standard Media | I31: Posters | J31: 24"W x 36"H | K31: Your ad will appear at an approved installation facility. | L31: 3 | N31: 400 | O31: 800 | P31: 1600 | Q31: 101 | R31: =IF(ISNUMBER(M31),ROUND(M31/(1-Settings!$B$2)/Settings!$B$3,0)*Settings!$B$3,"") | S31: =IF(ISNUMBER(N31),ROUND(N31/(1-Settings!$B$2)/Settings!$B$3,0)*Settings!$B$3,"") | T31: =IF(ISNUMBER(O31),ROUND(O31/(1-Settings!$B$2)/Settings!$B$3,0)*Settings!$B$3,"") | U31: =IF(ISNUMBER(P31),ROUND(P31/(1-Settings!$B$2)/Settings!$B$3,0)*Settings!$B$3,"") | V31: =IF(ISNUMBER(Q31),ROUND(Q31/(1-Settings!$B$2)/Settings!$B$3,0)*Settings!$B$3,"") | W31: 5504 | X31: 7035 | AC31: MasterMilitaryOnBaseList 12.2.25 NS.xlsx | AD31: Sponsorship & Advertising Rate Sheet_2026.pdf | AE31: Open in Box | AF31: Open in Box
A32: AK-JBERELME-019 | B32: JBER - Elmendorf AFB | D32: AK | E32: Anchorage | G32: Air Force | H32: Web & Email | I32: Web Ad | K32: Your ad will appear on the installation MWR / FSS website. | L32: 3 | N32: 800 | R32: =IF(ISNUMBER(M32),ROUND(M32/(1-Settings!$B$2)/Settings!$B$3,0)*Settings!$B$3,"") | S32: =IF(ISNUMBER(N32),ROUND(N32/(1-Settings!$B$2)/Settings!$B$3,0)*Settings!$B$3,"") | T32: =IF(ISNUMBER(O32),ROUND(O32/(1-Settings!$B$2)/Settings!$B$3,0)*Settings!$B$3,"") | U32: =IF(ISNUMBER(P32),ROUND(P32/(1-Settings!$B$2)/Settings!$B$3,0)*Settings!$B$3,"") | V32: =IF(ISNUMBER(Q32),ROUND(Q32/(1-Settings!$B$2)/Settings!$B$3,0)*Settings!$B$3,"") | W32: 5504 | X32: 7035 | Y32: 2026 | Z32: 2026-06 | AA32: Sold quarterly | AC32: Military - National Publication Inventory Master_June 2026.xlsx | AD32: Sponsorship & Advertising Rate Sheet_2026.pdf | AE32: Open in Box | AF32: Open in Box
A33: AL-FORTNOVO-001 | B33: Fort Novosel | C33: Fort Rucker | D33: AL | E33: Montgomery | F33: 36323 | G33: Army | H33: Digital | I33: Bowling Scoring Monitors | K33: Your ad will appear on all digital scoring monitors. | L33: 1 | M33: 200 | N33: 600 | O33: 1200 | P33: 2400 | Q33: 0 | R33: =IF(ISNUMBER(M33),ROUND(M33/(1-Settings!$B$2)/Settings!$B$3,0)*Settings!$B$3,"") | S33: =IF(ISNUMBER(N33),ROUND(N33/(1-Settings!$B$2)/Settings!$B$3,0)*Settings!$B$3,"") | T33: =IF(ISNUMBER(O33),ROUND(O33/(1-Settings!$B$2)/Settings!$B$3,0)*Settings!$B$3,"") | U33: =IF(ISNUMBER(P33),ROUND(P33/(1-Settings!$B$2)/Settings!$B$3,0)*Settings!$B$3,"") | V33: =IF(ISNUMBER(Q33),ROUND(Q33/(1-Settings!$B$2)/Settings!$B$3,0)*Settings!$B$3,"") | W33: 3860 | X33: 5945 | AC33: MasterMilitaryOnBaseList 12.2.25 NS.xlsx | AD33: Gate Marquees - Rucker_Specs.docx | AE33: Open in Box | AF33: Open in Box
A34: AL-FORTNOVO-002 | B34: Fort Novosel | C34: Fort Rucker | D34: AL | E34: Montgomery | F34: 36322 | G34: Army | H34: Digital | I34: Digital Monitor Network | K34: Your ad will appear on 11 digital monitors in approved installation facilities. | L34: 1 | M34: 250 | N34: 600 | O34: 1050 | P34: 1800 | Q34: 0 | R34: =IF(ISNUMBER(M34),ROUND(M34/(1-Settings!$B$2)/Settings!$B$3,0)*Settings!$B$3,"") | S34: =IF(ISNUMBER(N34),ROUND(N34/(1-Settings!$B$2)/Settings!$B$3,0)*Settings!$B$3,"") | T34: =IF(ISNUMBER(O34),ROUND(O34/(1-Settings!$B$2)/Settings!$B$3,0)*Settings!$B$3,"") | U34: =IF(ISNUMBER(P34),ROUND(P34/(1-Settings!$B$2)/Settings!$B$3,0)*Settings!$B$3,"") | V34: =IF(ISNUMBER(Q34),ROUND(Q34/(1-Settings!$B$2)/Settings!$B$3,0)*Settings!$B$3,"") | W34: 3860 | X34: 5945 | AC34: MasterMilitaryOnBaseList 12.2.25 NS.xlsx | AD34: Gate Marquees - Rucker_Specs.docx | AE34: Open in Box | AF34: Open in Box
A35: AL-FORTNOVO-003 | B35: Fort Novosel | C35: Fort Rucker | D35: AL | E35: Montgomery | F35: 36322 | G35: Army | H35: Digital | I35: Digital Signage (Gate Marquees) | K35: Your ad will appear on the digital gate marquees at the Ozark, Daleville, and Enterprise entrances reaching 26,000+ daily visitors. | L35: 1 | M35: 1000 | N35: 3000 | O35: 6000 | P35: 12000 | R35: =IF(ISNUMBER(M35),ROUND(M35/(1-Settings!$B$2)/Settings!$B$3,0)*Settings!$B$3,"") | S35: =IF(ISNUMBER(N35),ROUND(N35/(1-Settings!$B$2)/Settings!$B$3,0)*Settings!$B$3,"") | T35: =IF(ISNUMBER(O35),ROUND(O35/(1-Settings!$B$2)/Settings!$B$3,0)*Settings!$B$3,"") | U35: =IF(ISNUMBER(P35),ROUND(P35/(1-Settings!$B$2)/Settings!$B$3,0)*Settings!$B$3,"") | V35: =IF(ISNUMBER(Q35),ROUND(Q35/(1-Settings!$B$2)/Settings!$B$3,0)*Settings!$B$3,"") | W35: 3860 | X35: 5945 | AC35: MasterMilitaryOnBaseList 12.2.25 NS.xlsx | AD35: Gate Marquees - Rucker_Specs.docx | AE35: Open in Box | AF35: Open in Box
A36: AL-FORTNOVO-004 | B36: Fort Novosel | C36: Fort Rucker | D36: AL | E36: Montgomery | F36: 36322 | G36: Army | H36: Digital | I36: Digital Signage (Gate Marquees) | K36: Your ad will appear on the digital gate marquees at the Ozark, Daleville, and Enterprise entrances reaching 26,000+ daily visitors plus Silver Wings Golf Club marquee. | L36: 1 | M36: 1200 | N36: 3600 | O36: 7200 | P36: 14400 | R36: =IF(ISNUMBER(M36),ROUND(M36/(1-Settings!$B$2)/Settings!$B$3,0)*Settings!$B$3,"") | S36: =IF(ISNUMBER(N36),ROUND(N36/(1-Settings!$B$2)/Settings!$B$3,0)*Settings!$B$3,"") | T36: =IF(ISNUMBER(O36),ROUND(O36/(1-Settings!$B$2)/Settings!$B$3,0)*Settings!$B$3,"") | U36: =IF(ISNUMBER(P36),ROUND(P36/(1-Settings!$B$2)/Settings!$B$3,0)*Settings!$B$3,"") | V36: =IF(ISNUMBER(Q36),ROUND(Q36/(1-Settings!$B$2)/Settings!$B$3,0)*Settings!$B$3,"") | W36: 3860 | X36: 5945 | AC36: MasterMilitaryOnBaseList 12.2.25 NS.xlsx | AD36: Gate Marquees - Rucker_Specs.docx | AE36: Open in Box | AF36: Open in Box
A37: AL-FORTNOVO-005 | B37: Fort Novosel | C37: Fort Rucker | D37: AL | E37: Montgomery | F37: 36322 | G37: Army | H37: Digital | I37: Digital Signage (Gate Marquees) | K37: Your ad will appear on the Silver Wings Golf Club outdoor digital marquee | L37: 1 | M37: 400 | N37: 1200 | O37: 2400 | P37: 4800 | R37: =IF(ISNUMBER(M37),ROUND(M37/(1-Settings!$B$2)/Settings!$B$3,0)*Settings!$B$3,"") | S37: =IF(ISNUMBER(N37),ROUND(N37/(1-Settings!$B$2)/Settings!$B$3,0)*Settings!$B$3,"") | T37: =IF(ISNUMBER(O37),ROUND(O37/(1-Settings!$B$2)/Settings!$B$3,0)*Settings!$B$3,"") | U37: =IF(ISNUMBER(P37),ROUND(P37/(1-Settings!$B$2)/Settings!$B$3,0)*Settings!$B$3,"") | V37: =IF(ISNUMBER(Q37),ROUND(Q37/(1-Settings!$B$2)/Settings!$B$3,0)*Settings!$B$3,"") | W37: 3860 | X37: 5945 | AC37: MasterMilitaryOnBaseList 12.2.25 NS.xlsx | AD37: Gate Marquees - Rucker_Specs.docx | AE37: Open in Box | AF37: Open in Box
A38: AL-FORTNOVO-009 | B38: Fort Novosel | C38: Fort Rucker | D38: AL | E38: Montgomery | F38: 36322 | G38: Army | H38: Large Format | I38: Indoor Vinyl Banner and Counter Wraps | J38: Sizes Vary | K38: Your signs will be placed on the fencing that surrounds the ball fields, Lake Tholocco, the Lemon Lot, and The Flightline. | L38: 1 | M38: 1000 | N38: 3000 | O38: 6000 | P38: 12000 | R38: =IF(ISNUMBER(M38),ROUND(M38/(1-Settings!$B$2)/Settings!$B$3,0)*Settings!$B$3,"") | S38: =IF(ISNUMBER(N38),ROUND(N38/(1-Settings!$B$2)/Settings!$B$3,0)*Settings!$B$3,"") | T38: =IF(ISNUMBER(O38),ROUND(O38/(1-Settings!$B$2)/Settings!$B$3,0)*Settings!$B$3,"") | U38: =IF(ISNUMBER(P38),ROUND(P38/(1-Settings!$B$2)/Settings!$B$3,0)*Settings!$B$3,"") | V38: =IF(ISNUMBER(Q38),ROUND(Q38/(1-Settings!$B$2)/Settings!$B$3,0)*Settings!$B$3,"") | W38: 3860 | X38: 5945 | AC38: MasterMilitaryOnBaseList 12.2.25 NS.xlsx | AD38: Gate Marquees - Rucker_Specs.docx | AE38: Open in Box | AF38: Open in Box
A39: AL-FORTNOVO-016 | B39: Fort Novosel | D39: AL | E39: Montgomery | G39: Army | H39: Print & Publications | I39: Calendar Ad | K39: Your ad will appear in the installation events calendar. | L39: 1 | M39: 200 | R39: =IF(ISNUMBER(M39),ROUND(M39/(1-Settings!$B$2)/Settings!$B$3,0)*Settings!$B$3,"") | S39: =IF(ISNUMBER(N39),ROUND(N39/(1-Settings!$B$2)/Settings!$B$3,0)*Settings!$B$3,"") | T39: =IF(ISNUMBER(O39),ROUND(O39/(1-Settings!$B$2)/Settings!$B$3,0)*Settings!$B$3,"") | U39: =IF(ISNUMBER(P39),ROUND(P39/(1-Settings!$B$2)/Settings!$B$3,0)*Settings!$B$3,"") | V39: =IF(ISNUMBER(Q39),ROUND(Q39/(1-Settings!$B$2)/Settings!$B$3,0)*Settings!$B$3,"") | W39: 3860 | X39: 5945 | Y39: 2026 | Z39: 2026-06 | AC39: Military - National Publication Inventory Master_June 2026.xlsx | AD39: Gate Marquees - Rucker_Specs.docx | AE39: Open in Box | AF39: Open in Box
A40: AL-FORTNOVO-010 | B40: Fort Novosel | C40: Fort Rucker | D40: AL | E40: Montgomery | F40: 36322 | G40: Army | H40: Print & Publications | I40: Real Estate/Magazine Racks | K40: Your publication will be placed at one or more of the following locations on post (AAFES PX, Soldier Service Center, Silver Wings Golf Club, Shoppette/Mini Mall, Commissary, Lyster Health Clinic) *Price is per location | L40: 12 | P40: 250 | R40: =IF(ISNUMBER(M40),ROUND(M40/(1-Settings!$B$2)/Settings!$B$3,0)*Settings!$B$3,"") | S40: =IF(ISNUMBER(N40),ROUND(N40/(1-Settings!$B$2)/Settings!$B$3,0)*Settings!$B$3,"") | T40: =IF(ISNUMBER(O40),ROUND(O40/(1-Settings!$B$2)/Settings!$B$3,0)*Settings!$B$3,"") | U40: =IF(ISNUMBER(P40),ROUND(P40/(1-Settings!$B$2)/Settings!$B$3,0)*Settings!$B$3,"") | V40: =IF(ISNUMBER(Q40),ROUND(Q40/(1-Settings!$B$2)/Settings!$B$3,0)*Settings!$B$3,"") | W40: 3860 | X40: 5945 | AA40: Inventory master 6/2026 lists Magazine Ad at $1,200 (1 mo) | AC40: MasterMilitaryOnBaseList 12.2.25 NS.xlsx | AD40: Gate Marquees - Rucker_Specs.docx | AE40: Open in Box | AF40: Open in Box
...

Sheet Bases
A1: Base | B1: Also known as | C1: State | D1: DMA / Metro | E1: Zip | F1: Branch | G1: Media options | H1: Digital | I1: Standard Media | J1: Large Format | K1: Print & Pubs | L1: Web & Email | M1: Active Duty (ref.) | N1: Dependents (ref.) | O1: Rate card year(s) | P1: Rows needing review
A2: Eielson AFB | C2: AK | D2: Fairbanks | E2: 99702 | F2: Air Force | G2: 8 | H2: 2 | I2: 2 | J2: 0 | K2: 1 | L2: 2 | M2: 1958 | N2: 2424 | O2: 2026 | P2: 0
A3: Fort Greely | C3: AK | D3: Fairbanks, AK | F3: Army | G3: 2 | H3: 1 | I3: 0 | J3: 0 | K3: 0 | L3: 1 | O3: 2026 | P3: 0
A4: Fort Jonathan Wainwright | C4: AK | D4: Fairbanks, AK | F4: Army | G4: 2 | H4: 1 | I4: 0 | J4: 0 | K4: 0 | L4: 1 | M4: 6117 | N4: 6995 | O4: 2026 | P4: 0
A5: JBER - Elmendorf AFB | B5: Joint Base Elmendorf-Richardson | C5: AK | D5: Anchorage | E5: 99506 | F5: Air Force | G5: 19 | H5: 4 | I5: 4 | J5: 1 | K5: 5 | L5: 1 | M5: 5504 | N5: 7035 | O5: 2026 | P5: 0
A6: Fort Novosel | B6: Fort Rucker | C6: AL | D6: Montgomery | E6: 36323 | F6: Army | G6: 18 | H6: 5 | I6: 3 | J6: 1 | K6: 4 | L6: 4 | M6: 3860 | N6: 5945 | O6: 2026 | P6: 0
A7: Maxwell AFB (Incl. Gunter) | B7: Maxwell-Gunter AFB | C7: AL | D7: Montgomery-Selma | E7: 36112 | F7: Air Force | G7: 5 | H7: 3 | I7: 0 | J7: 0 | K7: 1 | L7: 1 | M7: 3012 | N7: 5336 | O7: 2026 | P7: 1
A8: Redstone Arsenal | C8: AL | D8: Huntsville-Decatur (Flor) | E8: 35898 | F8: Army | G8: 16 | H8: 5 | I8: 4 | J8: 3 | K8: 1 | L8: 2 | M8: 588 | N8: 1518 | O8: 2026 | P8: 0
A9: Little Rock AFB | C9: AR | D9: Little Rock-Pine Bluff | E9: 72099 | F9: Air Force | G9: 19 | H9: 6 | I9: 3 | J9: 7 | K9: 0 | L9: 2 | M9: 3536 | N9: 4572 | O9: 2026 | P9: 0
A10: Davis-Monthan Air Force Base | C10: AZ | D10: Tucson (Sierra Vista), AZ | F10: Air Force | G10: 3 | H10: 1 | I10: 0 | J10: 0 | K10: 1 | L10: 1 | M10: 5995 | N10: 6924 | O10: 2026 | P10: 0
A11: Fort Huachuca | C11: AZ | D11: Tucson (Sierra Vista), AZ | F11: Army | G11: 3 | H11: 1 | I11: 0 | J11: 0 | K11: 1 | L11: 1 | M11: 4139 | N11: 5163 | O11: 2026 | P11: 0
A12: Luke AFB | C12: AZ | D12: Phoenix (Prescott) | E12: 85309 | F12: Air Force | G12: 12 | H12: 2 | I12: 3 | J12: 0 | K12: 5 | L12: 1 | M12: 4607 | N12: 5689 | O12: 2026 | P12: 0
A13: Yuma MCAS | C13: AZ | D13: Yuma-El Centro | E13: 85369 | F13: Marine Corps | G13: 7 | H13: 4 | I13: 1 | J13: 0 | K13: 0 | L13: 2 | M13: 4946 | N13: 4702 | O13: 2026 | P13: 1
A14: 29 Palms MC Air/Ground Combat Center | C14: CA | D14: Los Angeles | E14: 92278 | F14: Marine Corps | G14: 21 | H14: 5 | I14: 1 | J14: 13 | K14: 1 | L14: 1 | O14: 2023 | P14: 20
A15: Beale AFB | C15: CA | D15: Sacramnto-Stkton-Modesto | E15: 95903 | F15: Air Force | G15: 10 | H15: 2 | I15: 4 | J15: 1 | K15: 1 | L15: 0 | P15: 3
A16: Camp Pendleton | C16: CA | D16: San Diego | F16: Marine Corps | G16: 22 | H16: 6 | I16: 2 | J16: 10 | K16: 2 | L16: 2 | M16: 39690 | N16: 31010 | O16: 2026 | P16: 4
A17: China Lake NAVWEAPCEN | B17: NAWS China Lake | C17: CA | D17: Los Angeles | E17: 93555 | F17: Navy | G17: 11 | H17: 1 | I17: 7 | J17: 1 | K17: 2 | L17: 0 | P17: 1
A18: Edwards AFB | C18: CA | D18: Los Angeles | E18: 93524 | F18: Air Force | G18: 13 | H18: 6 | I18: 4 | J18: 0 | K18: 3 | L18: 0 | P18: 1
A19: Fort Irwin | C19: CA | D19: Los Angeles | E19: 92310 | F19: Army | G19: 4 | H19: 2 | I19: 1 | J19: 1 | K19: 0 | L19: 0 | P19: 2
A20: Lemoore NAS | C20: CA | D20: Fresno-Visalia | E20: 93246 | F20: Navy | G20: 26 | H20: 4 | I20: 12 | J20: 10 | K20: 0 | L20: 0 | P20: 0
A21: Los Angeles AFB | C21: CA | D21: Los Angeles | E21: 90245 | F21: Air Force | G21: 11 | H21: 4 | I21: 2 | J21: 1 | K21: 1 | L21: 3 | P21: 1
A22: MCAS Miramar | C22: CA | D22: San Diego | E22: 92145 | F22: Marine Corps | G22: 7 | H22: 2 | I22: 1 | J22: 1 | K22: 0 | L22: 3 | M22: 7535 | N22: 7007 | O22: 2026 | P22: 1
A23: NBVC Port Hueneme NCBC | B23: Naval Base Ventura County | C23: CA | D23: Los Angeles | E23: 93043 | F23: Navy | G23: 62 | H23: 14 | I23: 3 | J23: 43 | K23: 0 | L23: 0 | P23: 1
A24: Point Loma | B24: Naval Base Point Loma (San Diego) | C24: CA | D24: San Diego | E24: 92106 | F24: Navy | G24: 6 | H24: 3 | I24: 0 | J24: 0 | K24: 0 | L24: 3 | M24: 32983 | N24: 33574 | O24: 2026 | P24: 1
A25: Travis AFB | C25: CA | D25: Sacramnto-Stkton-Modesto | E25: 94535 | F25: Air Force | G25: 12 | H25: 4 | I25: 3 | J25: 0 | K25: 3 | L25: 2 | M25: 6675 | N25: 7960 | O25: 2020 | P25: 1
A26: Buckley AFB | C26: CO | D26: Denver | E26: 80011 | F26: Air Force | G26: 5 | H26: 3 | I26: 0 | J26: 0 | K26: 1 | L26: 1 | M26: 2540 | N26: 3106 | O26: 2026 | P26: 0
A27: Fort Carson | C27: CO | D27: Colorado Springs-Pueblo | E27: 80913 | F27: Army | G27: 39 | H27: 10 | I27: 7 | J27: 9 | K27: 8 | L27: 2 | M27: 24520 | N27: 32953 | O27: 2026 | P27: 12
A28: Peterson AFB | C28: CO | D28: Colorado Springs-Pueblo | E28: 80914 | F28: Air Force | G28: 8 | H28: 2 | I28: 0 | J28: 5 | K28: 0 | L28: 1 | M28: 3645 | N28: 6210 | O28: 2026 | P28: 2
A29: Schriever AFB | C29: CO | D29: Colorado Springs-Pueblo | E29: 80912 | F29: Air Force | G29: 5 | H29: 1 | I29: 1 | J29: 1 | K29: 1 | L29: 1 | M29: 1853 | N29: 2679 | O29: 2026 | P29: 1
A30: USAF Academy | C30: CO | D30: Colorado Springs-Pueblo | E30: 80840 | F30: Air Force | G30: 12 | H30: 2 | I30: 1 | J30: 0 | K30: 7 | L30: 2 | M30: 2070 | N30: 3209 | O30: 2026 | P30: 2
A31: New London NAVSUBBASE (Groton) | C31: CT | D31: Hartford-New Haven, CT | F31: Navy | G31: 3 | H31: 2 | I31: 0 | J31: 0 | K31: 0 | L31: 1 | M31: 6385 | N31: 7471 | O31: 2026 | P31: 0
A32: JBAB Anacostia NS | B32: JB Anacostia-Bolling | C32: DC | D32: Washington, DC (Hagrstwn) | E32: 20332 | F32: Navy | G32: 8 | H32: 1 | I32: 2 | J32: 1 | K32: 0 | L32: 4 | M32: 2491 | N32: 3654 | O32: 2026 | P32: 0
A33: Washington NAVDIST HQ | B33: Naval District Washington / Washington Navy Yard | C33: DC | D33: Washington, DC (Hagrstwn) | E33: 20374 | F33: Navy | G33: 11 | H33: 5 | I33: 2 | J33: 1 | K33: 0 | L33: 3 | M33: 3100 | N33: 5435 | O33: 2026 | P33: 0
A34: Dover AFB | C34: DE | D34: Philadelphia | E34: 19902 | F34: Air Force | G34: 12 | H34: 3 | I34: 4 | J34: 2 | K34: 0 | L34: 1 | M34: 3484 | N34: 4234 | O34: 2026 | P34: 11
A35: Eglin AFB | C35: FL | D35: Mobile-Pensacola (Ft Walt) | E35: 32542 | F35: Air Force | G35: 18 | H35: 1 | I35: 7 | J35: 5 | K35: 4 | L35: 1 | M35: 9243 | N35: 12793 | O35: 2026 | P35: 5
A36: Homestead AFB | C36: FL | D36: Miami-Ft. Lauderdale | E36: 33039 | F36: Air Force | G36: 1 | H36: 0 | I36: 0 | J36: 0 | K36: 0 | L36: 0 | M36: 429 | N36: 718 | P36: 1
A37: Hurlburt Field | C37: FL | D37: Mobile-Pensacola (Ft Walt) | E37: 32544 | F37: Air Force | G37: 10 | H37: 2 | I37: 4 | J37: 1 | K37: 2 | L37: 1 | M37: 8185 | N37: 10597 | O37: 2026 | P37: 0
A38: Jacksonville NAS | C38: FL | D38: Jacksonville | E38: 32212 | F38: Navy | G38: 14 | H38: 2 | I38: 4 | J38: 4 | K38: 2 | L38: 2 | M38: 6967 | N38: 9499 | O38: 2026 | P38: 0
A39: Key West NAS | C39: FL | D39: Miami-Ft. Lauderdale | E39: 33040 | F39: Navy | G39: 11 | H39: 3 | I39: 3 | J39: 2 | K39: 1 | L39: 2 | M39: 797 | N39: 986 | O39: 2026 | P39: 0
A40: MacDill AFB | C40: FL | D40: Tampa-St. Pete (Sarasota) | E40: 33621 | F40: Air Force | G40: 6 | H40: 3 | I40: 2 | J40: 0 | K40: 0 | L40: 1 | M40: 5705 | N40: 10061 | O40: 2026 | P40: 0
...

Sheet Change Log
A1: Date | B1: Who | C1: Base | D1: What changed | E1: Rate card / source used
A2: 2026-09-29 | B2: Claude (for Jon) | C2: All | D2: Initial standardized master built from MasterMilitaryOnBaseList 12.2.25 NS.xlsx; client prices converted to margin-driven formulas; categories assigned; review flags added. | E2: Box > Military > Master Grid
